2025-03-23 19:14:31,049 - __main__ - INFO - Logger initialized successfully.
2025-03-23 19:15:59,052 - __main__ - INFO - Logging started...
2025-03-23 19:17:28,743 - networksecurity.logging.logger - INFO - Logging started...
2025-03-23 19:19:23,533 - networksecurity.logging.logger - INFO - Logging started...
2025-03-23 19:19:23,533 - networksecurity.logging.logger - ERROR - Error occurred in file: <stdin> at line 4 in function: <module>, with code: 500 and message: This is a test exception
2025-03-23 19:20:32,325 - networksecurity.logging.logger - INFO - Logging started...
2025-03-23 19:20:32,325 - networksecurity.logging.logger - ERROR - Custom message: This is a test exception
2025-03-23 19:20:32,325 - networksecurity.logging.logger - ERROR - Error occurred in file: <stdin> at line 3 in function: <module>, with code: 500 and message: This is a test exception
Traceback (most recent call last):
  File "<stdin>", line 3, in <module>
ZeroDivisionError: division by zero
2025-03-23 19:24:17,473 - networksecurity.logging.logger - INFO - __main__
2025-03-23 19:24:17,531 - networksecurity.logging.logger - ERROR - An exception occurred:
2025-03-23 19:24:17,531 - networksecurity.logging.logger - ERROR - Error occurred in file: <stdin> at line 3 in function: <module>, with code: 500 and message: Failed to divide numbers
Traceback (most recent call last):
  File "<stdin>", line 3, in <module>
  File "<stdin>", line 2, in divide_numbers
ZeroDivisionError: division by zero
