2025-03-23 19:24:37,519 - networksecurity.logging.logger - INFO - Logging started...
2025-03-23 19:24:37,519 - networksecurity.logging.logger - INFO - __main__
2025-03-23 19:24:37,519 - networksecurity.logging.logger - ERROR - An exception occurred:
2025-03-23 19:24:37,519 - networksecurity.logging.logger - ERROR - Error occurred in file: E:\Personal Laptop Python Projects And Studying Drafts\9- End-To-End ML Model With Deployment\test.py at line 14 in function: <module>, with code: 500 and message: Failed to divide numbers
Traceback (most recent call last):
  File "E:\Personal Laptop Python Projects And Studying Drafts\9- End-To-End ML Model With Deployment\test.py", line 14, in <module>
    result = divide_numbers(5, 0)
  File "E:\Personal Laptop Python Projects And Studying Drafts\9- End-To-End ML Model With Deployment\test.py", line 10, in divide_numbers
    return a / b
ZeroDivisionError: division by zero
